Workbook

Sheet Q&A Engine
A1: LOCUS · PSYCHOMETRIC SCORING ENGINE · 25-QUESTION INSTRUMENT
A2: Holland (RIASEC) · Big Five (OCEAN) · Self-Determination Theory · Multiple Intelligences · Career Decision-Making
A4: SCORE COLUMNS → H = Holland RIASEC | O = Big Five OCEAN | S = Self-Determination Theory | M = Multiple Intelligences | D = Decision-Making Readiness
A5: Q# | B5: Question / Scenario | C5: Answer Option | D5: H | E5: O | F5: S | G5: M | H5: D | I5: Theory Focus | J5: Construct Measured
A6: 1 | B6: Your college fest committee needs volunteers. Which role do you sign up for without hesitation? | C6: A — Set up and manage the stage equipment and sound system | D6: 5 | E6: 1 | F6: 3 | G6: 2 | H6: 2 | I6: Holland | J6: Realistic (R)
C7: B — Research and design the event theme with data from past fests | D7: 2 | E7: 4 | F7: 4 | G7: 3 | H7: 3 | I7: Holland + SDT | J7: Investigative (I) + Autonomy
C8: C — Coordinate all volunteers, make sure everyone has a role | D8: 2 | E8: 3 | F8: 4 | G8: 5 | H8: 4 | I8: Holland + MI | J8: Social (S) + Interpersonal Intel
C9: D — Promote the fest on social media and design creatives | D9: 3 | E9: 2 | F9: 3 | G9: 4 | H9: 3 | I9: Holland | J9: Artistic (A)
C10: E — Handle registrations, budget tracking, and vendor payments | D10: 2 | E10: 4 | F10: 2 | G10: 2 | H10: 4 | I10: Holland | J10: Conventional (C)
A11: 2 | B11: You have a major exam in 3 weeks and a club event happening this weekend. What do you actually do? | C11: A — Skip the event, start studying immediately with a fixed schedule | D11: 2 | E11: 5 | F11: 2 | G11: 2 | H11: 5 | I11: Big Five | J11: Conscientiousness (High)
C12: B — Attend the event but study every other day leading up to the exam | D12: 3 | E12: 3 | F12: 3 | G12: 3 | H12: 3 | I12: Big Five | J12: Conscientiousness (Mid)
C13: C — Attend the event and cram the night before the exam | D13: 4 | E13: 1 | F13: 2 | G13: 3 | H13: 1 | I13: Big Five | J13: Conscientiousness (Low)
C14: D — Delegate your club responsibilities to someone else so you can prepare | D14: 3 | E14: 4 | F14: 4 | G14: 3 | H14: 4 | I14: Big Five + SDT | J14: Conscientiousness + Competence
A15: 3 | B15: You get two internship offers. Offer A pays ₹25,000/month in a field you find boring. Offer B pays ₹8,000 in a field that genuinely interests you. What do you pick? | C15: A — Offer A. Money now is more important | D15: 2 | E15: 3 | F15: 1 | G15: 2 | H15: 3 | I15: SDT | J15: Extrinsic Motivation
C16: B — Offer B. The learning matters more than the pay at this stage | D16: 4 | E16: 3 | F16: 5 | G16: 4 | H16: 4 | I16: SDT | J16: Intrinsic Motivation + Autonomy
C17: C — Negotiate Offer B's pay upward before deciding | D17: 3 | E17: 4 | F17: 4 | G17: 3 | H17: 5 | I17: SDT + CDM | J17: Autonomy + Decision-Making
C18: D — Ask family, then decide based on their input | D18: 2 | E18: 2 | F18: 2 | G18: 2 | H18: 2 | I18: SDT | J18: Extrinsic + Relatedness low
A19: 4 | B19: A friend describes their startup idea to you. What's the first thing your mind does? | C19: A — Start calculating if the numbers actually work — market size, costs, margins | D19: 2 | E19: 5 | F19: 3 | G19: 1 | H19: 4 | I19: MI | J19: Logical-Mathematical
C20: B — Think about how to tell the story to investors or customers | D20: 3 | E20: 2 | F20: 3 | G20: 5 | H20: 3 | I20: MI | J20: Linguistic
C21: C — Visualise the product — what it looks like, how it flows | D21: 3 | E21: 2 | F21: 3 | G21: 4 | H21: 3 | I21: MI | J21: Spatial
C22: D — Immediately think about the team — who's needed, what roles | D22: 2 | E22: 3 | F22: 4 | G22: 5 | H22: 3 | I22: MI | J22: Interpersonal
C23: E — Ask whether this idea actually solves a real human problem | D23: 4 | E23: 3 | F23: 5 | G23: 3 | H23: 4 | I23: MI + SDT | J23: Intrapersonal + Competence
A24: 5 | B24: You're given free time and a small budget of ₹5,000. You most naturally… | C24: A — Start a small resale or service business to turn a profit | D24: 5 | E24: 3 | F24: 4 | G24: 3 | H24: 4 | I24: Holland | J24: Enterprising (E)
C25: B — Use it to attend a skill workshop or online course | D25: 3 | E25: 4 | F25: 4 | G25: 3 | H25: 4 | I25: Holland + SDT | J25: Investigative + Competence
C26: C — Organise a community event or help someone in need | D26: 2 | E26: 3 | F26: 3 | G26: 5 | H26: 3 | I26: Holland | J26: Social (S)
C27: D — Spend it on art supplies, music gear, or creative tools | D27: 3 | E27: 1 | F27: 4 | G27: 4 | H27: 2 | I27: Holland | J27: Artistic (A)
A28: 6 | B28: Your professor gives a completely unconventional assignment — no rules, just 'submit something meaningful'. You feel… | C28: A — Excited. This is when I do my best work | D28: 5 | E28: 4 | F28: 5 | G28: 5 | H28: 3 | I28: Big Five | J28: Openness (High)
C29: B — Curious but a little anxious — you'll work through it | D29: 4 | E29: 3 | F29: 4 | G29: 4 | H29: 3 | I29: Big Five | J29: Openness (Mid-High)
C30: C — Frustrated. You prefer clear guidelines and rubrics | D30: 2 | E30: 5 | F30: 2 | G30: 2 | H30: 4 | I30: Big Five | J30: Openness (Low)
C31: D — Indifferent. You'll just do the minimum needed to pass | D31: 1 | E31: 2 | F31: 1 | G31: 2 | H31: 2 | I31: Big Five | J31: Low engagement
A32: 7 | B32: When someone asks you 'what do you want to do after graduation?', you typically… | C32: A — Have a clear, specific answer with a plan already in motion | D32: 4 | E32: 4 | F32: 5 | G32: 4 | H32: 5 | I32: CDM | J32: Crystallization stage
C33: B — Have a few options you're seriously considering but haven't decided | D33: 4 | E33: 3 | F33: 4 | G33: 4 | H33: 4 | I33: CDM | J33: Exploration stage
C34: C — Give a vague answer because you genuinely haven't thought deeply about it | D34: 2 | E34: 2 | F34: 2 | G34: 2 | H34: 2 | I34: CDM | J34: Pre-contemplation
C35: D — Get anxious — you worry you're behind everyone else | D35: 2 | E35: 2 | F35: 2 | G35: 2 | H35: 1 | I35: CDM | J35: Decision paralysis
A36: 8 | B36: You have to explain a complex topic to your class. You instinctively create… | C36: A — A visual diagram, infographic, or sketch | D36: 3 | E36: 2 | F36: 4 | G36: 5 | H36: 3 | I36: MI | J36: Spatial Intelligence
C37: B — A well-structured written explanation with examples | D37: 4 | E37: 3 | F37: 3 | G37: 5 | H37: 3 | I37: MI | J37: Linguistic Intelligence
C38: C — A live demonstration or hands-on activity | D38: 4 | E38: 2 | F38: 4 | G38: 3 | H38: 3 | I38: MI | J38: Bodily-Kinesthetic
C39: D — A story or analogy that makes it relatable | D39: 3 | E39: 2 | F39: 4 | G39: 4 | H39: 3 | I39: MI | J39: Linguistic + Interpersonal
C40: E — A spreadsheet or data breakdown | D40: 2 | E40: 5 | F40: 3 | G40: 1 | H40: 4 | I40: MI | J40: Logical-Mathematical
A41: 9 | B41: Your ideal study or work environment is… | C41: A — A busy café or co-working space with ambient noise | D41: 4 | E41: 2 | F41: 3 | G41: 3 | H41: 3 | I41: Big Five | J41: Extraversion (High)
...

Sheet Student Calculator
A1: LOCUS — STUDENT RESPONSE SHEET & COMPOSITE CAREER FIT CALCULATOR
A2: INSTRUCTIONS: For each question, paste or type the scores from the Q&A Engine sheet for the option the student selected.
A3: Q# | B3: Student Selected Answer (paste option text) | C3: Holland (H) | D3: OCEAN (O) | E3: SDT (S) | F3: MI (M) | G3: CDM (D)
A4: 1 | B4: [Paste student's answer here] | C4: 0 | D4: 0 | E4: 0 | F4: 0 | G4: 0
A5: 2 | B5: [Paste student's answer here] | C5: 0 | D5: 0 | E5: 0 | F5: 0 | G5: 0
A6: 3 | B6: [Paste student's answer here] | C6: 0 | D6: 0 | E6: 0 | F6: 0 | G6: 0
A7: 4 | B7: [Paste student's answer here] | C7: 0 | D7: 0 | E7: 0 | F7: 0 | G7: 0
A8: 5 | B8: [Paste student's answer here] | C8: 0 | D8: 0 | E8: 0 | F8: 0 | G8: 0
A9: 6 | B9: [Paste student's answer here] | C9: 0 | D9: 0 | E9: 0 | F9: 0 | G9: 0
A10: 7 | B10: [Paste student's answer here] | C10: 0 | D10: 0 | E10: 0 | F10: 0 | G10: 0
A11: 8 | B11: [Paste student's answer here] | C11: 0 | D11: 0 | E11: 0 | F11: 0 | G11: 0
A12: 9 | B12: [Paste student's answer here] | C12: 0 | D12: 0 | E12: 0 | F12: 0 | G12: 0
A13: 10 | B13: [Paste student's answer here] | C13: 0 | D13: 0 | E13: 0 | F13: 0 | G13: 0
A14: 11 | B14: [Paste student's answer here] | C14: 0 | D14: 0 | E14: 0 | F14: 0 | G14: 0
A15: 12 | B15: [Paste student's answer here] | C15: 0 | D15: 0 | E15: 0 | F15: 0 | G15: 0
... A28: 25 | B28: [Paste student's answer here] | C28: 0 | D28: 0 | E28: 0 | F28: 0 | G28: 0
A29: TOTAL | B29: Raw Score (max 125 per theory) | C29: =SUM(C4:C28) -> 0 | D29: =SUM(D4:D28) -> 0 | E29: =SUM(E4:E28) -> 0 | F29: =SUM(F4:F28) -> 0 | G29: =SUM(G4:G28) -> 0
A30: SCORE % | B30: Normalised 0–100 per theory (÷125 × 100) | C30: =ROUND(C29/125*100,1) -> 0.0% | D30: =ROUND(D29/125*100,1) -> 0.0% | E30: =ROUND(E29/125*100,1) -> 0.0% | F30: =ROUND(F29/125*100,1) -> 0.0% | G30: =ROUND(G29/125*100,1) -> 0.0%
A32: COMPOSITE CAREER FIT SCORE (CCFS) — THE MASTER FORMULA
A33: CCFS Formula: | C33: =(C30*0.25 + D30*0.2 + E30*0.25 + F30*0.2 + G30*0.1) -> 0
A34: CCFS Result: | C34: =ROUND(C30*0.25 + D30*0.2 + E30*0.25 + F30*0.2 + G30*0.1, 1) -> 0
A35: WEIGHTS: Holland 25% | OCEAN 20% | SDT 25% | MI 20% | CDM 10%
A36: Motivation Quality Override: If SDT score < 50, apply 0.85× multiplier to CCFS (extrinsic motivation risk flag)
A37: Adjusted CCFS (with SDT flag): | C37: =IF(E30<50, ROUND(C34*0.85,1), C34) -> 0

Sheet Career Match Engine
A1: LOCUS — 127 CAREER PATH MATCHING ENGINE
A2: Each career has a SUCCESS PROFILE (expected scores). Delta = |Student Score − Success Profile|. Lower delta = better fit.
A3: # | B3: Career Path | C3: Domain | D3: H✓ | E3: O✓ | F3: S✓ | G3: M✓ | H3: D✓ | I3: Δ Holland | J3: Δ OCEAN | K3: Δ SDT | L3: Δ MI | M3: Fit Score (100) | N3: Status
A4: 1 | B4: Medical Doctor (MBBS→MD) | C4: Medicine | D4: 85 | E4: 75 | F4: 80 | G4: 70 | H4: 80 | I4: =ABS('Student Calculator'!C30-D4) -> 85 | J4: =ABS('Student Calculator'!D30-E4) -> 75 | K4: =ABS('Student Calculator'!E30-F4) -> 80 | L4: =ABS('Student Calculator'!F30-G4) -> 70 | M4: =ROUND(MAX(0, 100 - (I4*0.25 + J4*0.2 + K4*0.25 + L4*0.2)), 1) -> 29.8 | N4: =IF(M4>=72,"🟢 BEST FIT",IF(M4>=52,"🟡 CONSIDER","🔴 MISMATCH")) -> 🔴 MISMATCH
A5: 2 | B5: Surgeon | C5: Medicine | D5: 85 | E5: 80 | F5: 75 | G5: 75 | H5: 80 | I5: =ABS('Student Calculator'!C30-D5) -> 85 | J5: =ABS('Student Calculator'!D30-E5) -> 80 | K5: =ABS('Student Calculator'!E30-F5) -> 75 | L5: =ABS('Student Calculator'!F30-G5) -> 75 | M5: =ROUND(MAX(0, 100 - (I5*0.25 + J5*0.2 + K5*0.25 + L5*0.2)), 1) -> 29 | N5: =IF(M5>=72,"🟢 BEST FIT",IF(M5>=52,"🟡 CONSIDER","🔴 MISMATCH")) -> 🔴 MISMATCH
A6: 3 | B6: Dentist | C6: Medicine | D6: 80 | E6: 75 | F6: 75 | G6: 70 | H6: 75 | I6: =ABS('Student Calculator'!C30-D6) -> 80 | J6: =ABS('Student Calculator'!D30-E6) -> 75 | K6: =ABS('Student Calculator'!E30-F6) -> 75 | L6: =ABS('Student Calculator'!F30-G6) -> 70 | M6: =ROUND(MAX(0, 100 - (I6*0.25 + J6*0.2 + K6*0.25 + L6*0.2)), 1) -> 32.3 | N6: =IF(M6>=72,"🟢 BEST FIT",IF(M6>=52,"🟡 CONSIDER","🔴 MISMATCH")) -> 🔴 MISMATCH
A7: 4 | B7: Pharmacist | C7: Medicine | D7: 70 | E7: 80 | F7: 70 | G7: 65 | H7: 75 | I7: =ABS('Student Calculator'!C30-D7) -> 70 | J7: =ABS('Student Calculator'!D30-E7) -> 80 | K7: =ABS('Student Calculator'!E30-F7) -> 70 | L7: =ABS('Student Calculator'!F30-G7) -> 65 | M7: =ROUND(MAX(0, 100 - (I7*0.25 + J7*0.2 + K7*0.25 + L7*0.2)), 1) -> 36 | N7: =IF(M7>=72,"🟢 BEST FIT",IF(M7>=52,"🟡 CONSIDER","🔴 MISMATCH")) -> 🔴 MISMATCH
A8: 5 | B8: Biomedical Researcher | C8: Research | D8: 60 | E8: 90 | F8: 80 | G8: 65 | H8: 80 | I8: =ABS('Student Calculator'!C30-D8) -> 60 | J8: =ABS('Student Calculator'!D30-E8) -> 90 | K8: =ABS('Student Calculator'!E30-F8) -> 80 | L8: =ABS('Student Calculator'!F30-G8) -> 65 | M8: =ROUND(MAX(0, 100 - (I8*0.25 + J8*0.2 + K8*0.25 + L8*0.2)), 1) -> 34 | N8: =IF(M8>=72,"🟢 BEST FIT",IF(M8>=52,"🟡 CONSIDER","🔴 MISMATCH")) -> 🔴 MISMATCH
A9: 6 | B9: Geneticist | C9: Research | D9: 55 | E9: 90 | F9: 80 | G9: 60 | H9: 80 | I9: =ABS('Student Calculator'!C30-D9) -> 55 | J9: =ABS('Student Calculator'!D30-E9) -> 90 | K9: =ABS('Student Calculator'!E30-F9) -> 80 | L9: =ABS('Student Calculator'!F30-G9) -> 60 | M9: =ROUND(MAX(0, 100 - (I9*0.25 + J9*0.2 + K9*0.25 + L9*0.2)), 1) -> 36.3 | N9: =IF(M9>=72,"🟢 BEST FIT",IF(M9>=52,"🟡 CONSIDER","🔴 MISMATCH")) -> 🔴 MISMATCH
A10: 7 | B10: Microbiologist | C10: Research | D10: 55 | E10: 85 | F10: 80 | G10: 60 | H10: 75 | I10: =ABS('Student Calculator'!C30-D10) -> 55 | J10: =ABS('Student Calculator'!D30-E10) -> 85 | K10: =ABS('Student Calculator'!E30-F10) -> 80 | L10: =ABS('Student Calculator'!F30-G10) -> 60 | M10: =ROUND(MAX(0, 100 - (I10*0.25 + J10*0.2 + K10*0.25 + L10*0.2)), 1) -> 37.3 | N10: =IF(M10>=72,"🟢 BEST FIT",IF(M10>=52,"🟡 CONSIDER","🔴 MISMATCH")) -> 🔴 MISMATCH
A11: 8 | B11: Biochemist | C11: Research | D11: 55 | E11: 85 | F11: 80 | G11: 60 | H11: 75 | I11: =ABS('Student Calculator'!C30-D11) -> 55 | J11: =ABS('Student Calculator'!D30-E11) -> 85 | K11: =ABS('Student Calculator'!E30-F11) -> 80 | L11: =ABS('Student Calculator'!F30-G11) -> 60 | M11: =ROUND(MAX(0, 100 - (I11*0.25 + J11*0.2 + K11*0.25 + L11*0.2)), 1) -> 37.3 | N11: =IF(M11>=72,"🟢 BEST FIT",IF(M11>=52,"🟡 CONSIDER","🔴 MISMATCH")) -> 🔴 MISMATCH
A12: 9 | B12: Neuroscientist | C12: Research | D12: 55 | E12: 90 | F12: 85 | G12: 60 | H12: 80 | I12: =ABS('Student Calculator'!C30-D12) -> 55 | J12: =ABS('Student Calculator'!D30-E12) -> 90 | K12: =ABS('Student Calculator'!E30-F12) -> 85 | L12: =ABS('Student Calculator'!F30-G12) -> 60 | M12: =ROUND(MAX(0, 100 - (I12*0.25 + J12*0.2 + K12*0.25 + L12*0.2)), 1) -> 35 | N12: =IF(M12>=72,"🟢 BEST FIT",IF(M12>=52,"🟡 CONSIDER","🔴 MISMATCH")) -> 🔴 MISMATCH
A13: 10 | B13: Clinical Psychologist | C13: Psychology | D13: 45 | E13: 70 | F13: 85 | G13: 75 | H13: 80 | I13: =ABS('Student Calculator'!C30-D13) -> 45 | J13: =ABS('Student Calculator'!D30-E13) -> 70 | K13: =ABS('Student Calculator'!E30-F13) -> 85 | L13: =ABS('Student Calculator'!F30-G13) -> 75 | M13: =ROUND(MAX(0, 100 - (I13*0.25 + J13*0.2 + K13*0.25 + L13*0.2)), 1) -> 38.5 | N13: =IF(M13>=72,"🟢 BEST FIT",IF(M13>=52,"🟡 CONSIDER","🔴 MISMATCH")) -> 🔴 MISMATCH
A14: 11 | B14: Psychiatrist | C14: Psychology | D14: 50 | E14: 75 | F14: 85 | G14: 70 | H14: 80 | I14: =ABS('Student Calculator'!C30-D14) -> 50 | J14: =ABS('Student Calculator'!D30-E14) -> 75 | K14: =ABS('Student Calculator'!E30-F14) -> 85 | L14: =ABS('Student Calculator'!F30-G14) -> 70 | M14: =ROUND(MAX(0, 100 - (I14*0.25 + J14*0.2 + K14*0.25 + L14*0.2)), 1) -> 37.3 | N14: =IF(M14>=72,"🟢 BEST FIT",IF(M14>=52,"🟡 CONSIDER","🔴 MISMATCH")) -> 🔴 MISMATCH
A15: 12 | B15: Physiotherapist | C15: Medicine | D15: 80 | E15: 65 | F15: 75 | G15: 75 | H15: 70 | I15: =ABS('Student Calculator'!C30-D15) -> 80 | J15: =ABS('Student Calculator'!D30-E15) -> 65 | K15: =ABS('Student Calculator'!E30-F15) -> 75 | L15: =ABS('Student Calculator'!F30-G15) -> 75 | M15: =ROUND(MAX(0, 100 - (I15*0.25 + J15*0.2 + K15*0.25 + L15*0.2)), 1) -> 33.3 | N15: =IF(M15>=72,"🟢 BEST FIT",IF(M15>=52,"🟡 CONSIDER","🔴 MISMATCH")) -> 🔴 MISMATCH
A16: 13 | B16: Occupational Therapist | C16: Medicine | D16: 75 | E16: 65 | F16: 75 | G16: 75 | H16: 70 | I16: =ABS('Student Calculator'!C30-D16) -> 75 | J16: =ABS('Student Calculator'!D30-E16) -> 65 | K16: =ABS('Student Calculator'!E30-F16) -> 75 | L16: =ABS('Student Calculator'!F30-G16) -> 75 | M16: =ROUND(MAX(0, 100 - (I16*0.25 + J16*0.2 + K16*0.25 + L16*0.2)), 1) -> 34.5 | N16: =IF(M16>=72,"🟢 BEST FIT",IF(M16>=52,"🟡 CONSIDER","🔴 MISMATCH")) -> 🔴 MISMATCH
A17: 14 | B17: Nutritionist/Dietitian | C17: Medicine | D17: 65 | E17: 70 | F17: 75 | G17: 65 | H17: 70 | I17: =ABS('Student Calculator'!C30-D17) -> 65 | J17: =ABS('Student Calculator'!D30-E17) -> 70 | K17: =ABS('Student Calculator'!E30-F17) -> 75 | L17: =ABS('Student Calculator'!F30-G17) -> 65 | M17: =ROUND(MAX(0, 100 - (I17*0.25 + J17*0.2 + K17*0.25 + L17*0.2)), 1) -> 38 | N17: =IF(M17>=72,"🟢 BEST FIT",IF(M17>=52,"🟡 CONSIDER","🔴 MISMATCH")) -> 🔴 MISMATCH
A18: 15 | B18: Veterinarian | C18: Medicine | D18: 80 | E18: 70 | F18: 75 | G18: 65 | H18: 70 | I18: =ABS('Student Calculator'!C30-D18) -> 80 | J18: =ABS('Student Calculator'!D30-E18) -> 70 | K18: =ABS('Student Calculator'!E30-F18) -> 75 | L18: =ABS('Student Calculator'!F30-G18) -> 65 | M18: =ROUND(MAX(0, 100 - (I18*0.25 + J18*0.2 + K18*0.25 + L18*0.2)), 1) -> 34.3 | N18: =IF(M18>=72,"🟢 BEST FIT",IF(M18>=52,"🟡 CONSIDER","🔴 MISMATCH")) -> 🔴 MISMATCH
A19: 16 | B19: Environmental Scientist | C19: Science | D19: 60 | E19: 80 | F19: 80 | G19: 70 | H19: 70 | I19: =ABS('Student Calculator'!C30-D19) -> 60 | J19: =ABS('Student Calculator'!D30-E19) -> 80 | K19: =ABS('Student Calculator'!E30-F19) -> 80 | L19: =ABS('Student Calculator'!F30-G19) -> 70 | M19: =ROUND(MAX(0, 100 - (I19*0.25 + J19*0.2 + K19*0.25 + L19*0.2)), 1) -> 35 | N19: =IF(M19>=72,"🟢 BEST FIT",IF(M19>=52,"🟡 CONSIDER","🔴 MISMATCH")) -> 🔴 MISMATCH
A20: 17 | B20: Marine Biologist | C20: Science | D20: 65 | E20: 80 | F20: 80 | G20: 70 | H20: 65 | I20: =ABS('Student Calculator'!C30-D20) -> 65 | J20: =ABS('Student Calculator'!D30-E20) -> 80 | K20: =ABS('Student Calculator'!E30-F20) -> 80 | L20: =ABS('Student Calculator'!F30-G20) -> 70 | M20: =ROUND(MAX(0, 100 - (I20*0.25 + J20*0.2 + K20*0.25 + L20*0.2)), 1) -> 33.8 | N20: =IF(M20>=72,"🟢 BEST FIT",IF(M20>=52,"🟡 CONSIDER","🔴 MISMATCH")) -> 🔴 MISMATCH
A21: 18 | B21: Astronomer/Astrophysicist | C21: Science | D21: 40 | E21: 95 | F21: 85 | G21: 55 | H21: 80 | I21: =ABS('Student Calculator'!C30-D21) -> 40 | J21: =ABS('Student Calculator'!D30-E21) -> 95 | K21: =ABS('Student Calculator'!E30-F21) -> 85 | L21: =ABS('Student Calculator'!F30-G21) -> 55 | M21: =ROUND(MAX(0, 100 - (I21*0.25 + J21*0.2 + K21*0.25 + L21*0.2)), 1) -> 38.8 | N21: =IF(M21>=72,"🟢 BEST FIT",IF(M21>=52,"🟡 CONSIDER","🔴 MISMATCH")) -> 🔴 MISMATCH
A22: 19 | B22: Nuclear Engineer | C22: Engineering | D22: 75 | E22: 85 | F22: 70 | G22: 55 | H22: 75 | I22: =ABS('Student Calculator'!C30-D22) -> 75 | J22: =ABS('Student Calculator'!D30-E22) -> 85 | K22: =ABS('Student Calculator'!E30-F22) -> 70 | L22: =ABS('Student Calculator'!F30-G22) -> 55 | M22: =ROUND(MAX(0, 100 - (I22*0.25 + J22*0.2 + K22*0.25 + L22*0.2)), 1) -> 35.8 | N22: =IF(M22>=72,"🟢 BEST FIT",IF(M22>=52,"🟡 CONSIDER","🔴 MISMATCH")) -> 🔴 MISMATCH
A23: 20 | B23: Aerospace Engineer | C23: Engineering | D23: 80 | E23: 85 | F23: 70 | G23: 60 | H23: 75 | I23: =ABS('Student Calculator'!C30-D23) -> 80 | J23: =ABS('Student Calculator'!D30-E23) -> 85 | K23: =ABS('Student Calculator'!E30-F23) -> 70 | L23: =ABS('Student Calculator'!F30-G23) -> 60 | M23: =ROUND(MAX(0, 100 - (I23*0.25 + J23*0.2 + K23*0.25 + L23*0.2)), 1) -> 33.5 | N23: =IF(M23>=72,"🟢 BEST FIT",IF(M23>=52,"🟡 CONSIDER","🔴 MISMATCH")) -> 🔴 MISMATCH
A24: 21 | B24: Mechanical Engineer | C24: Engineering | D24: 85 | E24: 80 | F24: 65 | G24: 55 | H24: 75 | I24: =ABS('Student Calculator'!C30-D24) -> 85 | J24: =ABS('Student Calculator'!D30-E24) -> 80 | K24: =ABS('Student Calculator'!E30-F24) -> 65 | L24: =ABS('Student Calculator'!F30-G24) -> 55 | M24: =ROUND(MAX(0, 100 - (I24*0.25 + J24*0.2 + K24*0.25 + L24*0.2)), 1) -> 35.5 | N24: =IF(M24>=72,"🟢 BEST FIT",IF(M24>=52,"🟡 CONSIDER","🔴 MISMATCH")) -> 🔴 MISMATCH
A25: 22 | B25: Civil Engineer | C25: Engineering | D25: 80 | E25: 75 | F25: 65 | G25: 55 | H25: 75 | I25: =ABS('Student Calculator'!C30-D25) -> 80 | J25: =ABS('Student Calculator'!D30-E25) -> 75 | K25: =ABS('Student Calculator'!E30-F25) -> 65 | L25: =ABS('Student Calculator'!F30-G25) -> 55 | M25: =ROUND(MAX(0, 100 - (I25*0.25 + J25*0.2 + K25*0.25 + L25*0.2)), 1) -> 37.8 | N25: =IF(M25>=72,"🟢 BEST FIT",IF(M25>=52,"🟡 CONSIDER","🔴 MISMATCH")) -> 🔴 MISMATCH
A26: 23 | B26: Chemical Engineer | C26: Engineering | D26: 70 | E26: 85 | F26: 65 | G26: 55 | H26: 75 | I26: =ABS('Student Calculator'!C30-D26) -> 70 | J26: =ABS('Student Calculator'!D30-E26) -> 85 | K26: =ABS('Student Calculator'!E30-F26) -> 65 | L26: =ABS('Student Calculator'!F30-G26) -> 55 | M26: =ROUND(MAX(0, 100 - (I26*0.25 + J26*0.2 + K26*0.25 + L26*0.2)), 1) -> 38.3 | N26: =IF(M26>=72,"🟢 BEST FIT",IF(M26>=52,"🟡 CONSIDER","🔴 MISMATCH")) -> 🔴 MISMATCH
A27: 24 | B27: Electrical Engineer | C27: Engineering | D27: 80 | E27: 80 | F27: 65 | G27: 55 | H27: 75 | I27: =ABS('Student Calculator'!C30-D27) -> 80 | J27: =ABS('Student Calculator'!D30-E27) -> 80 | K27: =ABS('Student Calculator'!E30-F27) -> 65 | L27: =ABS('Student Calculator'!F30-G27) -> 55 | M27: =ROUND(MAX(0, 100 - (I27*0.25 + J27*0.2 + K27*0.25 + L27*0.2)), 1) -> 36.8 | N27: =IF(M27>=72,"🟢 BEST FIT",IF(M27>=52,"🟡 CONSIDER","🔴 MISMATCH")) -> 🔴 MISMATCH
A28: 25 | B28: Electronics Engineer | C28: Engineering | D28: 80 | E28: 80 | F28: 65 | G28: 55 | H28: 75 | I28: =ABS('Student Calculator'!C30-D28) -> 80 | J28: =ABS('Student Calculator'!D30-E28) -> 80 | K28: =ABS('Student Calculator'!E30-F28) -> 65 | L28: =ABS('Student Calculator'!F30-G28) -> 55 | M28: =ROUND(MAX(0, 100 - (I28*0.25 + J28*0.2 + K28*0.25 + L28*0.2)), 1) -> 36.8 | N28: =IF(M28>=72,"🟢 BEST FIT",IF(M28>=52,"🟡 CONSIDER","🔴 MISMATCH")) -> 🔴 MISMATCH
A29: 26 | B29: Computer Science Engineer | C29: Technology | D29: 55 | E29: 90 | F29: 70 | G29: 45 | H29: 80 | I29: =ABS('Student Calculator'!C30-D29) -> 55 | J29: =ABS('Student Calculator'!D30-E29) -> 90 | K29: =ABS('Student Calculator'!E30-F29) -> 70 | L29: =ABS('Student Calculator'!F30-G29) -> 45 | M29: =ROUND(MAX(0, 100 - (I29*0.25 + J29*0.2 + K29*0.25 + L29*0.2)), 1) -> 41.8 | N29: =IF(M29>=72,"🟢 BEST FIT",IF(M29>=52,"🟡 CONSIDER","🔴 MISMATCH")) -> 🔴 MISMATCH
A30: 27 | B30: Software Developer | C30: Technology | D30: 45 | E30: 90 | F30: 70 | G30: 45 | H30: 80 | I30: =ABS('Student Calculator'!C30-D30) -> 45 | J30: =ABS('Student Calculator'!D30-E30) -> 90 | K30: =ABS('Student Calculator'!E30-F30) -> 70 | L30: =ABS('Student Calculator'!F30-G30) -> 45 | M30: =ROUND(MAX(0, 100 - (I30*0.25 + J30*0.2 + K30*0.25 + L30*0.2)), 1) -> 44.3 | N30: =IF(M30>=72,"🟢 BEST FIT",IF(M30>=52,"🟡 CONSIDER","🔴 MISMATCH")) -> 🔴 MISMATCH
A31: 28 | B31: Data Scientist | C31: Technology | D31: 40 | E31: 95 | F31: 75 | G31: 40 | H31: 80 | I31: =ABS('Student Calculator'!C30-D31) -> 40 | J31: =ABS('Student Calculator'!D30-E31) -> 95 | K31: =ABS('Student Calculator'!E30-F31) -> 75 | L31: =ABS('Student Calculator'!F30-G31) -> 40 | M31: =ROUND(MAX(0, 100 - (I31*0.25 + J31*0.2 + K31*0.25 + L31*0.2)), 1) -> 44.3 | N31: =IF(M31>=72,"🟢 BEST FIT",IF(M31>=52,"🟡 CONSIDER","🔴 MISMATCH")) -> 🔴 MISMATCH
A32: 29 | B32: AI/ML Engineer | C32: Technology | D32: 40 | E32: 95 | F32: 75 | G32: 40 | H32: 80 | I32: =ABS('Student Calculator'!C30-D32) -> 40 | J32: =ABS('Student Calculator'!D30-E32) -> 95 | K32: =ABS('Student Calculator'!E30-F32) -> 75 | L32: =ABS('Student Calculator'!F30-G32) -> 40 | M32: =ROUND(MAX(0, 100 - (I32*0.25 + J32*0.2 + K32*0.25 + L32*0.2)), 1) -> 44.3 | N32: =IF(M32>=72,"🟢 BEST FIT",IF(M32>=52,"🟡 CONSIDER","🔴 MISMATCH")) -> 🔴 MISMATCH
A33: 30 | B33: Cybersecurity Analyst | C33: Technology | D33: 55 | E33: 90 | F33: 70 | G33: 40 | H33: 80 | I33: =ABS('Student Calculator'!C30-D33) -> 55 | J33: =ABS('Student Calculator'!D30-E33) -> 90 | K33: =ABS('Student Calculator'!E30-F33) -> 70 | L33: =ABS('Student Calculator'!F30-G33) -> 40 | M33: =ROUND(MAX(0, 100 - (I33*0.25 + J33*0.2 + K33*0.25 + L33*0.2)), 1) -> 42.8 | N33: =IF(M33>=72,"🟢 BEST FIT",IF(M33>=52,"🟡 CONSIDER","🔴 MISMATCH")) -> 🔴 MISMATCH
A34: 31 | B34: Cloud Solutions Architect | C34: Technology | D34: 55 | E34: 85 | F34: 70 | G34: 45 | H34: 80 | I34: =ABS('Student Calculator'!C30-D34) -> 55 | J34: =ABS('Student Calculator'!D30-E34) -> 85 | K34: =ABS('Student Calculator'!E30-F34) -> 70 | L34: =ABS('Student Calculator'!F30-G34) -> 45 | M34: =ROUND(MAX(0, 100 - (I34*0.25 + J34*0.2 + K34*0.25 + L34*0.2)), 1) -> 42.8 | N34: =IF(M34>=72,"🟢 BEST FIT",IF(M34>=52,"🟡 CONSIDER","🔴 MISMATCH")) -> 🔴 MISMATCH
A35: 32 | B35: DevOps Engineer | C35: Technology | D35: 65 | E35: 85 | F35: 65 | G35: 40 | H35: 75 | I35: =ABS('Student Calculator'!C30-D35) -> 65 | J35: =ABS('Student Calculator'!D30-E35) -> 85 | K35: =ABS('Student Calculator'!E30-F35) -> 65 | L35: =ABS('Student Calculator'!F30-G35) -> 40 | M35: =ROUND(MAX(0, 100 - (I35*0.25 + J35*0.2 + K35*0.25 + L35*0.2)), 1) -> 42.5 | N35: =IF(M35>=72,"🟢 BEST FIT",IF(M35>=52,"🟡 CONSIDER","🔴 MISMATCH")) -> 🔴 MISMATCH
A36: 33 | B36: UX/UI Designer | C36: Design | D36: 70 | E36: 65 | F36: 75 | G36: 90 | H36: 70 | I36: =ABS('Student Calculator'!C30-D36) -> 70 | J36: =ABS('Student Calculator'!D30-E36) -> 65 | K36: =ABS('Student Calculator'!E30-F36) -> 75 | L36: =ABS('Student Calculator'!F30-G36) -> 90 | M36: =ROUND(MAX(0, 100 - (I36*0.25 + J36*0.2 + K36*0.25 + L36*0.2)), 1) -> 32.8 | N36: =IF(M36>=72,"🟢 BEST FIT",IF(M36>=52,"🟡 CONSIDER","🔴 MISMATCH")) -> 🔴 MISMATCH
A37: 34 | B37: Product Manager | C37: Business | D37: 65 | E37: 75 | F37: 80 | G37: 75 | H37: 85 | I37: =ABS('Student Calculator'!C30-D37) -> 65 | J37: =ABS('Student Calculator'!D30-E37) -> 75 | K37: =ABS('Student Calculator'!E30-F37) -> 80 | L37: =ABS('Student Calculator'!F30-G37) -> 75 | M37: =ROUND(MAX(0, 100 - (I37*0.25 + J37*0.2 + K37*0.25 + L37*0.2)), 1) -> 33.8 | N37: =IF(M37>=72,"🟢 BEST FIT",IF(M37>=52,"🟡 CONSIDER","🔴 MISMATCH")) -> 🔴 MISMATCH
A38: 35 | B38: Business Analyst | C38: Business | D38: 50 | E38: 85 | F38: 70 | G38: 65 | H38: 85 | I38: =ABS('Student Calculator'!C30-D38) -> 50 | J38: =ABS('Student Calculator'!D30-E38) -> 85 | K38: =ABS('Student Calculator'!E30-F38) -> 70 | L38: =ABS('Student Calculator'!F30-G38) -> 65 | M38: =ROUND(MAX(0, 100 - (I38*0.25 + J38*0.2 + K38*0.25 + L38*0.2)), 1) -> 40 | N38: =IF(M38>=72,"🟢 BEST FIT",IF(M38>=52,"🟡 CONSIDER","🔴 MISMATCH")) -> 🔴 MISMATCH
A39: 36 | B39: Actuary | C39: Finance | D39: 35 | E39: 95 | F39: 65 | G39: 35 | H39: 85 | I39: =ABS('Student Calculator'!C30-D39) -> 35 | J39: =ABS('Student Calculator'!D30-E39) -> 95 | K39: =ABS('Student Calculator'!E30-F39) -> 65 | L39: =ABS('Student Calculator'!F30-G39) -> 35 | M39: =ROUND(MAX(0, 100 - (I39*0.25 + J39*0.2 + K39*0.25 + L39*0.2)), 1) -> 49 | N39: =IF(M39>=72,"🟢 BEST FIT",IF(M39>=52,"🟡 CONSIDER","🔴 MISMATCH")) -> 🔴 MISMATCH
A40: 37 | B40: Chartered Accountant | C40: Finance | D40: 40 | E40: 90 | F40: 60 | G40: 40 | H40: 85 | I40: =ABS('Student Calculator'!C30-D40) -> 40 | J40: =ABS('Student Calculator'!D30-E40) -> 90 | K40: =ABS('Student Calculator'!E30-F40) -> 60 | L40: =ABS('Student Calculator'!F30-G40) -> 40 | M40: =ROUND(MAX(0, 100 - (I40*0.25 + J40*0.2 + K40*0.25 + L40*0.2)), 1) -> 49 | N40: =IF(M40>=72,"🟢 BEST FIT",IF(M40>=52,"🟡 CONSIDER","🔴 MISMATCH")) -> 🔴 MISMATCH
...

Sheet Thresholds & Integration
A1: LOCUS — THRESHOLD LOGIC, CCFS FORMULA & SUPABASE INTEGRATION SPEC
A2: STATUS THRESHOLDS
A3: Fit Score ≥ 72 | B3: 🟢 BEST FIT — Show in top tier, highlighted | C3: Green card, shown first
A4: Fit Score 52–71 | B4: 🟡 CONSIDER — Show faded below top 3 | C4: Orange card, secondary
A5: Fit Score < 52 | B5: 🔴 MISMATCH — Filtered out / not shown | C5: Hidden or greyed out
A7: CCFS FORMULA WEIGHTS
A8: Holland RIASEC | B8: 25% weight | C8: Environment-person fit
A9: Big Five OCEAN | B9: 20% weight | C9: Persistence probability
A10: SDT Motivation | B10: 25% weight | C10: Intrinsic vs extrinsic flag
A11: Multiple Intelligence | B11: 20% weight | C11: Cognitive task alignment
A12: Career Decision-Making | B12: 10% weight | C12: Readiness stage factor
A14: SDT OVERRIDE RULE
A15: If SDT score < 50 | B15: Apply 0.85× multiplier to CCFS | C15: Risk flag: extrinsic motivation
A16: If SDT score < 35 | B16: Show warning in UI | C16: 'Your motivation appears external — explore why'
A18: SUPABASE SCHEMA
A19: Table: quiz_responses | B19: student_id, question_id, option_selected, h_score, o_score, s_score, m_score, d_score, created_at | C19: One row per question per student
A20: Table: student_profiles | B20: student_id, holland_total, ocean_total, sdt_total, mi_total, cdm_total, ccfs, adjusted_ccfs, created_at | C20: Computed after all 25 Q answered
A21: Table: career_paths | B21: career_id, name, domain, h_profile, o_profile, s_profile, m_profile, d_profile | C21: Static reference table
A22: Table: career_matches | B22: student_id, career_id, fit_score, status, rank, created_at | C22: Computed on quiz completion
A24: SUPABASE EDGE FUNCTION
A25: Trigger: | B25: On INSERT to quiz_responses where question_id = 25 | C25: Fires after final question
A26: Step 1: | B26: SELECT SUM scores grouped by student_id | C26: Aggregate all 25 answers
A27: Step 2: | B27: Normalise each theory score ÷ max × 100 | C27: Get 0-100 per theory
A28: Step 3: | B28: CCFS = H×0.25 + O×0.20 + S×0.25 + MI×0.20 + D×0.10 | C28: Weighted composite
A29: Step 4: | B29: IF SDT < 50: adjusted_ccfs = ccfs × 0.85 | C29: Apply override
A30: Step 5: | B30: For each career: fit_score = 100 − weighted delta from profile | C30: Match all 127 careers
A31: Step 6: | B31: INSERT into career_matches sorted by fit_score DESC | C31: Store results
A32: Step 7: | B32: Return top 3 (≥72), next tier (52-71) to frontend | C32: API response
A34: FRONTEND DISPLAY LOGIC
A35: Top 3 (BEST FIT) | B35: Full card, colour accent, rank 1–3 shown prominently | C35: Green border
A36: Next tier (CONSIDER) | B36: Faded card below fold, 60% opacity, swipeable | C36: Orange indicator
A37: MISMATCH | B37: Not shown unless student taps 'See all' | C37: Hidden by default
A39: API RESPONSE SHAPE
A40: JSON structure: | B40: { student_id, ccfs, adjusted_ccfs, sdt_flag: bool,
B41: top_matches: [{career_id, name, domain, fit_score, status, rank}],
B42: secondary_matches: [...], motivation_note: string }
